Response: Let's break down the thought process for analyzing the provided Go code snippet.

1. **Initial Read and Understanding the Core Goal:**  The first step is to quickly read the code and identify the primary actions. I see `defer func() {}`, `recover()`, and `panic(nil)`. This immediately suggests the code is playing around with panic and recover mechanisms in Go. The comment `// https://golang.org/issue/990` reinforces this idea, indicating a specific bug or behavior is being tested.

2. **Analyzing the `defer`red Function:** The `defer` keyword means the enclosed anonymous function will execute *after* the surrounding `main` function (or block) finishes, regardless of how it finishes (normal completion or a panic). Inside this function, `recover()` is called. `recover()`'s purpose is to intercept a panicking goroutine and return the value passed to `panic`. If no panic occurred, it returns `nil`.

3. **Analyzing the `panic(nil)`:**  The line `panic(nil)` is the key trigger. It explicitly initiates a panic with the value `nil`.

4. **Connecting the Pieces:** Now I connect the deferred function with the panic. When `panic(nil)` executes, the program starts unwinding the stack. Before exiting the `main` function, the deferred function runs. Inside this function, `recover()` will intercept the `nil` value passed to `panic`.

5. **Predicting the Outcome:** Since `recover()` returns `nil`, the `if recover() != nil` condition will be false. Therefore, the `panic("non-nil recover")` inside the `if` block will *not* be executed. The deferred function will complete, and because the `recover()` caught the initial panic, the program will terminate normally (exit code 0).

6. **Formulating the Functionality Summary:** Based on this analysis, I can summarize the code's function as demonstrating that `recover()` correctly handles a `panic(nil)` and doesn't cause a subsequent panic in the deferred function. It's essentially testing a specific edge case of `panic` and `recover`.

7. **Identifying the Go Feature:**  The core Go feature being demonstrated is the `panic` and `recover` mechanism for handling runtime errors.

8. **Creating an Illustrative Go Code Example:** To further clarify the concept, I need to create a simple example that contrasts the behavior of `recover()` with and without a panic. This helps solidify the understanding of how `recover()` works. The example should showcase both a successful recovery and a scenario where `recover()` returns `nil` because no panic occurred.

9. **Considering Command-Line Arguments:**  The provided code snippet doesn't use any command-line arguments. Therefore, this section is not applicable.

10. **Identifying Potential User Mistakes:** This is a crucial part. Users new to Go's `panic`/`recover` might make a few common errors:
    * **Misunderstanding `recover()`'s scope:** `recover()` only works within a `defer`red function. Calling it elsewhere will not intercept panics.
    * **Assuming `recover()` always returns an error:**  It returns `nil` if no panic occurred. Users might expect an error type.
    * **Not re-panic'ing if the error is unrecoverable:**  Sometimes, you might want to log the error and then re-panic to let the program terminate. Forgetting to re-panic might lead to unexpected behavior.
    * **Thinking `recover()` can handle all errors:** `recover()` is specifically for panics. Regular errors should be handled with standard error checking.

11. **Structuring the Output:**  Finally, I need to organize the analysis into a clear and logical structure, covering the requested points: functionality, Go feature, example code, code logic with input/output, command-line arguments (or lack thereof), and potential mistakes. Using headings and bullet points enhances readability.

**(Self-Correction/Refinement during the process):**

* **Initial thought:**  Could the `panic("non-nil recover")` ever be reached?  A closer look at the condition `recover() != nil` confirms it won't, as `recover()` will return `nil`.
* **Focusing on the *bug*:** The comment `// https://golang.org/issue/990` suggests this code might be a regression test or a demonstration of a fixed bug. The core takeaway is the *correct* behavior of `recover()` with `panic(nil)`.
* **Clarity of the example:** Ensuring the example clearly shows the difference between a recovered panic and no panic is essential for demonstrating the concept.

By following these steps, I can systematically analyze the provided Go code and generate a comprehensive and informative explanation.
这段Go语言代码片段主要的功能是**测试 `recover()` 函数在捕获到 `panic(nil)` 时的行为**。它验证了当使用 `panic(nil)` 触发 panic 时，`recover()` 函数能够正常捕获并返回 `nil`，而不会导致后续的 panic。

**它所实现的 Go 语言功能是 `panic` 和 `recover` 机制。**

`panic` 用于引发运行时错误，中断正常的程序执行流程。
`recover` 用于在 `defer` 调用的函数中捕获 `panic`，使得程序可以从 `panic` 状态恢复，继续执行后续的代码（或者至少优雅地终止）。

**Go 代码举例说明：**

```go
package main

import "fmt"

func mightPanic(input int) {
	if input < 0 {
		panic("Input cannot be negative")
	}
	if input == 0 {
		panic(nil) // 模拟代码片段中的 panic(nil)
	}
	fmt.Println("Processing:", input)
}

func main() {
	testCases := []int{-1, 0, 5}
	for _, tc := range testCases {
		fmt.Println("Testing with input:", tc)
		func() {
			defer func() {
				if r := recover(); r != nil {
					fmt.Println("Recovered from panic:", r)
				} else {
					fmt.Println("No panic occurred.")
				}
			}()
			mightPanic(tc)
			fmt.Println("This line will only be printed if no panic occurs.")
		}()
		fmt.Println("Finished testing with input:", tc, "\n")
	}
}
```

**代码逻辑介绍（带假设的输入与输出）：**

假设我们运行上面的 `main` 函数。

**输入：** `testCases` 包含了 `-1`, `0`, 和 `5` 三个整数作为 `mightPanic` 函数的输入。

**输出：**

```
Testing with input: -1
Recovered from panic: Input cannot be negative
Finished testing with input: -1

Testing with input: 0
Recovered from panic: <nil>
Finished testing with input: 0

Testing with input: 5
Processing: 5
This line will only be printed if no panic occurs.
Finished testing with input: 5
```

**逻辑分析：**

1. **`Testing with input: -1`**:
   - `mightPanic(-1)` 被调用。
   - 由于 `input < 0` 为真，`panic("Input cannot be negative")` 被执行。
   - `panic` 发生时，`defer` 语句定义的匿名函数开始执行。
   - `recover()` 捕获到 panic，并返回 `"Input cannot be negative"`。
   - `if r := recover(); r != nil` 条件成立。
   - 打印 "Recovered from panic: Input cannot be negative"。
   - 外层的匿名函数执行完毕。
   - 打印 "Finished testing with input: -1"。

2. **`Testing with input: 0`**:
   - `mightPanic(0)` 被调用。
   - 由于 `input == 0` 为真，`panic(nil)` 被执行。
   - `panic` 发生时，`defer` 语句定义的匿名函数开始执行。
   - `recover()` 捕获到 panic，并返回 `nil`。
   - `if r := recover(); r != nil` 条件不成立（因为 `r` 是 `nil`）。
   - 打印 "No panic occurred." （这里需要注意，虽然发生了 `panic(nil)`，但 `recover()` 捕获了它，所以从 `recover()` 的角度看，panic 已经被处理了）。
   - 外层的匿名函数执行完毕。
   - 打印 "Finished testing with input: 0"。

3. **`Testing with input: 5`**:
   - `mightPanic(5)` 被调用。
   - `if input < 0` 和 `if input == 0` 的条件都不成立。
   - 打印 "Processing: 5"。
   - `mightPanic` 函数正常返回。
   - `fmt.Println("This line will only be printed if no panic occurs.")` 被执行，打印该语句。
   - `defer` 语句定义的匿名函数开始执行。
   - `recover()` 返回 `nil`，因为没有发生 panic。
   - `if r := recover(); r != nil` 条件不成立。
   - 打印 "No panic occurred."
   - 外层的匿名函数执行完毕。
   - 打印 "Finished testing with input: 5"。

**命令行参数的具体处理：**

这段代码片段本身没有涉及到任何命令行参数的处理。它只是一个简单的测试用例，关注 `panic` 和 `recover` 的行为。

**使用者易犯错的点：**

1. **误解 `recover()` 的作用域：** `recover()` 必须在 `defer` 调用的函数中才能生效。如果在其他地方调用 `recover()`，它将始终返回 `nil`，即使有 panic 发生。

   ```go
   package main

   import "fmt"

   func main() {
       defer func() {
           fmt.Println("Deferred function executed")
       }()

       funcThatPanics := func() {
           panic("Something went wrong")
       }

       // 错误的用法：在 defer 外部调用 recover
       if r := recover(); r != nil {
           fmt.Println("Recovered:", r) // 这行代码不会被执行
       }

       funcThatPanics() // 引发 panic
   }
   ```

   在这个例子中，尽管 `funcThatPanics()` 会引发 panic，但由于 `recover()` 是在 `defer` 外部调用的，所以它不会捕获到 panic。程序会直接崩溃。

2. **认为 `recover()` 可以捕获所有类型的错误：** `recover()` 只能捕获由 `panic` 显式引发的运行时错误。它不能捕获普通的错误返回值（例如，函数返回 `error` 类型）。

   ```go
   package main

   import (
       "errors"
       "fmt"
   )

   func mightReturnError(input int) error {
       if input < 0 {
           return errors.New("Input cannot be negative")
       }
       return nil
   }

   func main() {
       defer func() {
           if r := recover(); r != nil {
               fmt.Println("Recovered:", r) // 对于 mightReturnError 返回的 error 无效
           }
       }()

       err := mightReturnError(-1)
       if err != nil {
           fmt.Println("Error occurred:", err) // 正确的处理方式
       }
   }
   ```

   在这个例子中，`mightReturnError` 返回了一个 `error` 类型的值。`recover()` 无法捕获这个错误。正确的做法是显式地检查和处理错误返回值。

3. **忘记在 `recover()` 后进行适当的处理：**  仅仅调用 `recover()` 来阻止程序崩溃可能是不够的。通常需要在 `recover()` 后记录错误信息、清理资源或者进行其他的善后处理。

   ```go
   package main

   import "fmt"

   func riskyOperation() {
       // ... 一些可能引发 panic 的操作 ...
       panic("Something critical failed")
   }

   func main() {
       defer func() {
           if r := recover(); r != nil {
               fmt.Println("Recovered from:", r)
               // 应该在这里记录错误，清理资源，或者采取其他措施
           }
       }()
       riskyOperation()
       fmt.Println("This line might not be reached")
   }
   ```

   在这个例子中，`recover()` 捕获了 panic，但仅仅打印了一条消息。在实际应用中，可能需要更完善的错误处理机制。

总而言之，`go/test/fixedbugs/bug301.go` 这段代码简洁地验证了 `recover()` 函数能够正确处理 `panic(nil)` 的情况，是理解 Go 语言错误处理机制的一个很好的例子。

Prompt: 
```
这是路径为go/test/fixedbugs/bug301.go的go语言实现的一部分， 请归纳一下它的功能, 　
如果你能推理出它是什么go语言功能的实现，请用go代码举例说明, 
如果介绍代码逻辑，则建议带上假设的输入与输出，
如果涉及命令行参数的具体处理，请详细介绍一下，
如果有哪些使用者易犯错的点，请举例说明，没有则不必说明，

"""
// compile

// Copyright 2010 The Go Authors. All rights reserved.
// Use of this source code is governed by a BSD-style
// license that can be found in the LICENSE file.

// https://golang.org/issue/990

package main

func main() {
	defer func() {
		if recover() != nil {
			panic("non-nil recover")
		}
	}()
	panic(nil)
}

"""



```