Response: Let's break down the thought process for analyzing the Go code snippet.

**1. Initial Understanding - What's the Goal?**

The comment "// Test recovering from runtime errors." immediately tells us the core purpose of this code. It's about demonstrating how Go's `recover()` mechanism handles runtime panics.

**2. Dissecting the `check` Function - The Heart of the Logic**

This function is clearly the central piece. Let's analyze its components:

* **`defer func() { ... }()`:**  The `defer` keyword is a strong indicator of error handling or cleanup. The anonymous function executed by `defer` will run *after* the `check` function's normal execution finishes, or if a panic occurs within it.
* **`v := recover()`:** This is the crucial part for panic recovery. If a panic occurred in the `f()` call, `recover()` will capture the value passed to `panic()`. If no panic occurred, `recover()` returns `nil`.
* **Error Checking within `defer`:** The code checks if `v` is `nil` (meaning no panic). If not, it checks if the recovered value is of type `runtime.Error`. This is important because runtime panics often use this specific error type.
* **String Matching:** The code then extracts the error message from the `runtime.Error` and uses `strings.Index` to see if it contains the expected error message (`err` argument to `check`).
* **`bug()` Function:** This function seems like a simple error reporting mechanism for the *test itself*. If any of the checks in the `defer` fail, it prints "BUG". This is common in testing frameworks to signal unexpected behavior.
* **`f()` Call:**  The `check` function takes a function `f` as an argument and executes it. This is where the code that might cause a panic will reside.

**3. Examining the `main` Function -  Scenarios for Panics**

The `main` function calls `check` multiple times, each time with a different function that's designed to trigger a specific type of runtime panic. Let's list these and identify the intended panic:

* **`check("int-div-zero", func() { println(1 / x) }, "integer divide by zero")`:**  Integer division by zero.
* **`check("int64-div-zero", func() { println(1 / x64) }, "integer divide by zero")`:**  Same, but with a 64-bit integer.
* **`check("nil-deref", func() { println(p[0]) }, "nil pointer dereference")`:** Accessing an element of a nil slice/array.
* **`check("nil-deref-1", func() { println(p[1]) }, "nil pointer dereference")`:**  Same as above.
* **`check("nil-deref-big", func() { println(q[5000]) }, "nil pointer dereference")`:** Same as above, even with a larger index.
* **`check("array-bounds", func() { println(p1[i]) }, "index out of range")`:** Accessing an array element beyond its bounds.
* **`check("slice-bounds", func() { println(sl[i]) }, "index out of range")`:** Accessing a slice element beyond its bounds.
* **`check("type-concrete", func() { println(inter.(string)) }, "int, not string")`:** Type assertion failure when the underlying type doesn't match.
* **`check("type-interface", func() { println(inter.(m)) }, "missing method m")`:** Type assertion failure on an interface when the underlying type doesn't implement the required methods.

**4. Inferring the Go Feature: Panic and Recover**

Based on the code's structure and the explicit mention of "recovering from runtime errors," it's clear that this code demonstrates the `panic` and `recover` mechanisms in Go. `panic` is used to signal an unrecoverable error, and `recover` allows a function to regain control after a panic, preventing the program from crashing entirely.

**5. Constructing the Example Code (Illustrative)**

To demonstrate `panic` and `recover`, we can create a simple example similar to the structure in `recover3.go`:

```go
package main

import "fmt"

func mightPanic(input int) {
	if input == 0 {
		panic("division by zero!")
	}
	fmt.Println(10 / input)
}

func safeOperation(val int) {
	defer func() {
		if r := recover(); r != nil {
			fmt.Println("Recovered from:", r)
		}
	}()
	mightPanic(val)
	fmt.Println("Operation completed successfully.") // This won't print if mightPanic panics
}

func main() {
	safeOperation(5)
	safeOperation(0)
	safeOperation(2)
}
```

**6. Considering Command-Line Arguments and Common Mistakes**

In this specific code snippet, there are *no* command-line arguments being processed. The code is entirely self-contained.

Regarding common mistakes:

* **Incorrectly assuming `recover()` catches all errors:**  `recover()` only catches panics. Regular errors (like those returned by functions) need to be handled through other means (e.g., `if err != nil`).
* **Not checking the return value of `recover()`:**  If `recover()` returns `nil`, it means no panic occurred, and trying to use the recovered value will lead to errors.
* **Placing `recover()` in the wrong scope:** `recover()` must be called directly within a deferred function. If called outside of a `defer`, it will always return `nil`.
* **Panic not being a `runtime.Error`:** While common for runtime issues, a `panic` can be called with any value. The provided code checks for `runtime.Error`, so users should be aware of this assumption.

**7. Review and Refinement**

Finally, review the analysis to ensure it's clear, accurate, and addresses all parts of the prompt. Organize the information logically and provide clear examples.
Let's break down the Go code snippet `go/test/recover3.go` step by step.

**Functionality:**

The primary function of this code is to test Go's `recover` mechanism for handling runtime panics. It sets up various scenarios that are known to cause runtime errors and verifies that `recover` can successfully catch these panics and inspect the error messages.

Specifically, it tests the following types of runtime errors:

* **Integer division by zero:** Attempting to divide an integer by zero.
* **Nil pointer dereference:** Trying to access a member or element of a nil pointer.
* **Array/slice bounds out of range:** Accessing an element of an array or slice using an index that is outside the valid range.
* **Type assertion failure:** Attempting to convert an interface value to a concrete type or another interface that it doesn't satisfy.

**Go Language Feature: Panic and Recover**

This code directly demonstrates the `panic` and `recover` built-in functions in Go.

* **`panic`:**  Used to signal an irrecoverable error during program execution. When `panic` is called, normal execution stops, and the program unwinds the call stack, executing deferred functions along the way.
* **`recover`:** A built-in function that can regain control of a panicking goroutine. It should be called directly by a deferred function. When a panic occurs, if a deferred function calls `recover`, the panic sequence stops, and `recover` returns the value passed to `panic`. If no panic is in progress, `recover` returns `nil`.

**Go Code Example Illustrating Panic and Recover:**

```go
package main

import (
	"fmt"
	"runtime"
)

func mightPanic(value int) {
	if value == 0 {
		panic("division by zero occurred")
	}
	fmt.Println("Result:", 100/value)
}

func safeOperation(input int) {
	defer func() {
		if r := recover(); r != nil {
			fmt.Println("Recovered from panic:", r)
			// Optionally, you can log the error or perform other cleanup actions.
			// You can also re-panic if the error is not handled.
		}
	}()
	mightPanic(input)
	fmt.Println("Operation completed successfully")
}

func main() {
	safeOperation(10) // This will execute normally
	safeOperation(0)  // This will cause a panic, which will be recovered.
	safeOperation(5)  // This will execute normally
}
```

**Hypothetical Input and Output for Code Reasoning:**

Let's trace the execution of the `main` function in `recover3.go`:

**Assumptions:** The code is executed without any modifications.

**Steps and Expected Output:**

1. **`check("int-div-zero", func() { println(1 / x) }, "integer divide by zero")`:**
   - `f()`: `println(1 / x)` where `x` is initialized to `0`. This causes a "integer divide by zero" panic.
   - `recover()` in the deferred function catches the panic.
   - The recovered value `v` is a `runtime.Error`.
   - `runt.Error()` returns a string containing "integer divide by zero".
   - The check passes, and no "BUG" is printed.

2. **`check("int64-div-zero", func() { println(1 / x64) }, "integer divide by zero")`:**
   - Similar to the above, but with an `int64`. A "integer divide by zero" panic occurs and is recovered.

3. **`check("nil-deref", func() { println(p[0]) }, "nil pointer dereference")`:**
   - `f()`: `println(p[0])` where `p` is a nil pointer. This causes a "nil pointer dereference" panic.
   - The panic is recovered, and the error message is checked.

4. **`check("nil-deref-1", func() { println(p[1]) }, "nil pointer dereference")`:**
   - Same as above.

5. **`check("nil-deref-big", func() { println(q[5000]) }, "nil pointer dereference")`:**
   - Same as above.

6. **`check("array-bounds", func() { println(p1[i]) }, "index out of range")`:**
   - `f()`: `println(p1[i])` where `i` is `99999`, which is out of bounds for `p1` (size 10). This causes an "index out of range" panic.

7. **`check("slice-bounds", func() { println(sl[i]) }, "index out of range")`:**
   - `f()`: `println(sl[i])` where `sl` is a nil slice and `i` is `99999`. This causes an "index out of range" panic.

8. **`check("type-concrete", func() { println(inter.(string)) }, "int, not string")`:**
   - `f()`: `println(inter.(string))` where `inter` holds an `int`. This causes a type assertion panic with the message containing "int, not string".

9. **`check("type-interface", func() { println(inter.(m)) }, "missing method m")`:**
   - `f()`: `println(inter.(m))` where `inter` holds an `int`, which doesn't implement the interface `m`. This causes a type assertion panic with a message indicating the missing method.

**Expected Standard Output (if no bugs are detected):**

The code is designed to test the `recover` mechanism. If all checks pass, the `bug()` function will not be called, and the output will be empty except for a potential panic at the very end if `didbug` is true (which should not happen in a successful test run).

**If a bug were detected (e.g., `recover` didn't work as expected for one of the scenarios), the output would include "BUG" followed by information about which check failed.**

**Command-Line Parameters:**

This specific Go source file (`recover3.go`) is designed as a test case and doesn't take any command-line parameters directly. When executed using `go run recover3.go`, it will simply run the `main` function.

However, within the Go testing framework, you might use commands like `go test recover3.go` or `go test -run Recover3` (assuming the package name allows for such targeted testing). These commands are part of the `go test` tool, not arguments parsed by the `recover3.go` code itself.

**Common Mistakes When Using `recover`:**

1. **Not Calling `recover` within a `defer`red function:**  `recover` only has an effect when called directly inside a `defer`red function. If called elsewhere, it will always return `nil`.

   ```go
   package main

   import "fmt"

   func mightPanic() {
       panic("something went wrong")
   }

   func tryRecover() {
       recover() // This will not catch the panic
       mightPanic()
   }

   func main() {
       tryRecover() // Program will still crash
       fmt.Println("This will not be printed")
   }
   ```

2. **Assuming `recover` catches all errors:** `recover` only handles panics. Regular errors returned by functions (e.g., from `os.Open`) need to be handled using error checking (`if err != nil`).

   ```go
   package main

   import (
       "fmt"
       "os"
   )

   func readFile(filename string) {
       defer func() {
           if r := recover(); r != nil {
               fmt.Println("Recovered:", r)
           }
       }()
       _, err := os.Open(filename)
       if err != nil {
           // This is a regular error, not a panic
           fmt.Println("Error opening file:", err)
           return // Or handle it in some other way
       }
       fmt.Println("File opened successfully")
   }

   func main() {
       readFile("nonexistent.txt") // This will print the error, but no panic to recover from
   }
   ```

3. **Not checking the return value of `recover`:** `recover` returns `nil` if no panic is in progress. Trying to use the return value without checking if it's `nil` can lead to unexpected behavior.

   ```go
   package main

   import "fmt"

   func noPanic() {
       defer func() {
           recoveredValue := recover()
           fmt.Println("Recovered value:", recoveredValue) // Will print "Recovered value: <nil>"
       }()
       fmt.Println("No panic here")
   }

   func main() {
       noPanic()
   }
   ```

4. **Re-panicking without careful consideration:**  After recovering from a panic, you can choose to re-panic (using `panic(recoveredValue)`). However, you should do this intentionally, usually after logging or performing some cleanup, and understand that the panic will continue to propagate up the call stack (unless caught by another `recover`).

This detailed breakdown should provide a comprehensive understanding of the `recover3.go` code and the `panic`/`recover` mechanism in Go.

Prompt: 
```
这是路径为go/test/recover3.go的go语言实现的一部分， 请列举一下它的功能, 　
如果你能推理出它是什么go语言功能的实现，请用go代码举例说明, 
如果涉及代码推理，需要带上假设的输入与输出，
如果涉及命令行参数的具体处理，请详细介绍一下，
如果有哪些使用者易犯错的点，请举例说明，没有则不必说明，

"""
// run

// Copyright 2010 The Go Authors. All rights reserved.
// Use of this source code is governed by a BSD-style
// license that can be found in the LICENSE file.

// Test recovering from runtime errors.

package main

import (
	"runtime"
	"strings"
)

var didbug bool

func bug() {
	if didbug {
		return
	}
	println("BUG")
	didbug = true
}

func check(name string, f func(), err string) {
	defer func() {
		v := recover()
		if v == nil {
			bug()
			println(name, "did not panic")
			return
		}
		runt, ok := v.(runtime.Error)
		if !ok {
			bug()
			println(name, "panicked but not with runtime.Error")
			return
		}
		s := runt.Error()
		if strings.Index(s, err) < 0 {
			bug()
			println(name, "panicked with", s, "not", err)
			return
		}
	}()

	f()
}

func main() {
	var x int
	var x64 int64
	var p *[10]int
	var q *[10000]int
	var i int

	check("int-div-zero", func() { println(1 / x) }, "integer divide by zero")
	check("int64-div-zero", func() { println(1 / x64) }, "integer divide by zero")

	check("nil-deref", func() { println(p[0]) }, "nil pointer dereference")
	check("nil-deref-1", func() { println(p[1]) }, "nil pointer dereference")
	check("nil-deref-big", func() { println(q[5000]) }, "nil pointer dereference")

	i = 99999
	var sl []int
	p1 := new([10]int)
	check("array-bounds", func() { println(p1[i]) }, "index out of range")
	check("slice-bounds", func() { println(sl[i]) }, "index out of range")

	var inter interface{}
	inter = 1
	check("type-concrete", func() { println(inter.(string)) }, "int, not string")
	check("type-interface", func() { println(inter.(m)) }, "missing method m")

	if didbug {
		panic("recover3")
	}
}

type m interface {
	m()
}

"""



```