Response: Let's break down the thought process for analyzing this Go code snippet.

**1. Initial Code Reading & High-Level Understanding:**

The first step is to read through the code and get a general idea of what's happening. We see a `main` function, a function `f`, and a function `g` (which is empty and seems irrelevant). The `main` function has a `defer` block, and the `f` function has a loop that attempts to iterate over a string.

**2. Focusing on the Potential Issue:**

The comment `// THIS IS LINE 17` next to the loop in `f` is a huge clue. It strongly suggests that this line is the focus of the bug or the test. The loop itself is interesting because it's trying to range over `*x`, where `x` is a `*string` initialized to `nil`. Dereferencing a `nil` pointer will cause a panic.

**3. Analyzing the `defer` Block:**

The `defer` block in `main` is crucial. It uses a `for` loop and `runtime.Caller` to walk up the call stack. The conditions inside the loop are looking for:

* The filename containing "bug348.go".
* The function name being "main.f".
* The line number being 17.

If all these conditions are met, it calls `recover()`. This indicates that the code is *intentionally* causing a panic in `f` and then recovering from it in the `defer` block.

**4. Formulating the Purpose/Function:**

Based on the above analysis, the code seems designed to test the behavior of `recover()` when a panic occurs within a specific function and line. It's verifying that `recover()` can be used to gracefully handle a deliberately induced panic.

**5. Developing a Hypothesis about the Go Feature:**

The core Go feature being demonstrated is the `panic` and `recover` mechanism. Specifically, it's showcasing how `recover` in a deferred function can intercept a panic.

**6. Creating a Minimal Example:**

To illustrate the concept, a simple example demonstrating `panic` and `recover` is needed. Something like this comes to mind:

```go
package main

import "fmt"

func mightPanic() {
    panic("Something went wrong!")
}

func main() {
    defer func() {
        if r := recover(); r != nil {
            fmt.Println("Recovered from:", r)
        }
    }()
    mightPanic()
    fmt.Println("This won't be printed")
}
```

This example captures the essence of the bug348 code without the complexities of stack tracing.

**7. Explaining the Code Logic with Hypothetical Input/Output:**

Since the code doesn't take user input, the "input" is more about the execution flow.

* **Input:** The program starts.
* **Process:** `main` calls `f`. `f` attempts to dereference a nil pointer, causing a panic at line 17. The `defer` function in `main` is then executed. It finds the panic occurred in `main.f` at line 17 and calls `recover()`, preventing the program from crashing.
* **Output:**  The `defer` block might print "BUG" messages if the stack trace doesn't match expectations. However, if everything works as intended, there will be no output from the `defer` block. The crucial point is the *absence* of a program crash.

**8. Addressing Command-Line Arguments:**

The code doesn't use any command-line arguments, so this section can be skipped.

**9. Identifying Potential User Mistakes:**

The most significant potential mistake is misunderstanding how `recover()` works. Specifically:

* **Incorrect placement of `recover()`:** If `recover()` is not called within a deferred function, it won't catch the panic.
* **Not checking the return value of `recover()`:** `recover()` returns `nil` if no panic occurred. Ignoring this can lead to unexpected behavior.

**10. Review and Refinement:**

Finally, review the analysis to ensure clarity, accuracy, and completeness. Check for any inconsistencies or areas that need further explanation. For instance, initially, I might not have explicitly mentioned the "test" nature of the code. Realizing that the `defer` block is *asserting* the panic happened at the expected location helps solidify this understanding.

This detailed breakdown shows how to approach the code, identify the core functionality, and explain it effectively, even with unusual or testing-specific code like this example.
这段 Go 代码的主要功能是**测试 `recover()` 函数在特定的堆栈帧中捕获 `panic` 的能力**。它特意制造了一个 `panic`，然后通过 `defer` 语句注册的匿名函数来捕获这个 `panic`，并对 `panic` 发生的位置进行断言。

**具体功能归纳：**

1. **制造 `panic`:**  `f()` 函数中声明了一个 `nil` 的字符串指针 `x`，然后在 `for...range` 循环中尝试解引用这个 `nil` 指针 (`*x`)，这将导致一个 `panic`。
2. **捕获 `panic`:** `main()` 函数中使用 `defer` 注册了一个匿名函数。当 `f()` 函数发生 `panic` 时，这个匿名函数会被执行。
3. **检查 `panic` 位置:**  匿名函数使用 `runtime.Caller` 函数遍历调用栈，查找 `panic` 发生的堆栈帧。它会检查：
    * 文件名是否包含 "bug348.go"。
    * 函数名是否是 "main.f"。
    * 行号是否是 17 (即 `for _, i := range *x` 这一行)。
4. **断言 `panic` 位置:** 如果 `panic` 发生的文件、函数和行号与预期不符，它会打印 "BUG" 消息。
5. **恢复 `panic`:** 如果 `panic` 发生在预期的位置，匿名函数会调用 `recover()` 函数来阻止程序崩溃。

**它是什么 go 语言功能的实现？**

这段代码是 Go 语言中 `panic` 和 `recover` 机制的一个测试用例。`panic` 用于抛出运行时错误，而 `recover` 用于在 `defer` 函数中捕获并处理这些错误，防止程序完全崩溃。

**Go 代码举例说明 `panic` 和 `recover` 的用法：**

```go
package main

import "fmt"

func mightPanic() {
	panic("Something went wrong!")
}

func main() {
	defer func() {
		if r := recover(); r != nil {
			fmt.Println("Recovered from:", r)
		}
	}()

	fmt.Println("Before the panic")
	mightPanic()
	fmt.Println("After the panic (this will not be printed)")
}
```

**代码逻辑介绍 (带假设的输入与输出)：**

**假设没有 `defer` 语句：**

* **输入:** 程序启动。
* **过程:** `main()` 函数调用 `f()` 函数。`f()` 函数执行到 `for _, i := range *x` 时，由于 `x` 是 `nil`，解引用操作会导致一个 `panic`。
* **输出:** 程序会因为 `panic` 而崩溃，并打印错误信息，例如："panic: runtime error: invalid memory address or nil pointer dereference"。

**假设有 `defer` 语句 (就像代码中的情况)：**

* **输入:** 程序启动。
* **过程:** `main()` 函数调用 `f()` 函数。`f()` 函数执行到 `for _, i := range *x` 时，发生 `panic`。
* **过程:** 由于存在 `defer` 语句，在 `panic` 发生后，注册的匿名函数会被执行。
* **过程:** 匿名函数遍历调用栈，找到 `panic` 发生在 "bug348.go" 文件的 "main.f" 函数的第 17 行。
* **过程:** 因为 `panic` 位置符合预期，匿名函数调用 `recover()`。
* **输出:** 程序不会崩溃。由于 `recover()` 返回的是 `panic` 的值 (在这里是 `nil`，因为是空指针解引用)，但代码中没有使用这个返回值，所以不会有额外的输出。如果 `panic` 发生在其他位置，则会打印 "BUG" 相关的错误信息。

**命令行参数的具体处理：**

这段代码本身不涉及任何命令行参数的处理。它是一个独立的 Go 源代码文件，可以直接使用 `go run bug348.go` 运行。

**使用者易犯错的点：**

一个常见的错误是**认为在 `panic` 发生后，所有后续的代码都会被跳过，包括 `defer` 语句之外的代码**。  实际上，`defer` 语句会在函数执行结束前（无论是正常结束还是发生 `panic`）都会被执行。

**举例说明：**

```go
package main

import "fmt"

func mightPanic() {
	panic("Something went wrong!")
}

func main() {
	defer func() {
		if r := recover(); r != nil {
			fmt.Println("Recovered from:", r)
		}
	}()

	fmt.Println("Before the panic")
	mightPanic()
	fmt.Println("After the panic (this will NOT be printed if there's no recover)")
}
```

如果 `defer` 中没有 `recover()`，`mightPanic()` 中的 `panic` 会导致程序崩溃， "After the panic" 这行代码不会被执行。但是，如果存在 `recover()`，即使 `mightPanic()` 发生了 `panic`，`recover()` 会捕获它，程序不会崩溃，但 "After the panic" 这行代码仍然不会被执行，因为 `panic` 之后的正常代码流程被中断了。

这段 `bug348.go` 的代码巧妙地利用 `panic` 和 `recover` 机制来测试 Go 运行时环境对 `panic` 发生位置的追踪是否准确。它不是一个常规的应用代码，而是一个用于测试特定 Go 语言特性的单元测试或基准测试。

### 提示词
```
这是路径为go/test/fixedbugs/bug348.go的go语言实现的一部分， 请归纳一下它的功能, 　
如果你能推理出它是什么go语言功能的实现，请用go代码举例说明, 
如果介绍代码逻辑，则建议带上假设的输入与输出，
如果涉及命令行参数的具体处理，请详细介绍一下，
如果有哪些使用者易犯错的点，请举例说明，没有则不必说明，
```

### 源代码
```
// run

// Copyright 2011 The Go Authors. All rights reserved.
// Use of this source code is governed by a BSD-style
// license that can be found in the LICENSE file.

package main

import (
	"runtime"
	"strings"
)

func f() {
	var x *string
	
	for _, i := range *x {  // THIS IS LINE 17
		println(i)
	}
}

func g() {
}

func main() {
	defer func() {
		for i := 0;; i++ {
			pc, file, line, ok := runtime.Caller(i)
			if !ok {
				print("BUG: bug348: cannot find caller\n")
				return
			}
			if !strings.Contains(file, "bug348.go") || runtime.FuncForPC(pc).Name() != "main.f" {
				// walk past runtime frames
				continue
			}
			if line != 17 {
				print("BUG: bug348: panic at ", file, ":", line, " in ", runtime.FuncForPC(pc).Name(), "\n")
				return
			}
			recover()
			return
		}
	}()
	f()
}
```