Response: Let's break down the thought process for analyzing this Go code snippet.

**1. Initial Code Scan and High-Level Understanding:**

The first step is to quickly read through the code, identifying key elements. I noticed:

* **`package main` and `func main()`:** This is an executable Go program.
* **`import "log"`:**  The program uses logging for error reporting.
* **`func expect(want, have interface{})`:** This looks like a helper function for making assertions. If `want` and `have` are different, it calls `log.Fatalf`, terminating the program.
* **Multiple nested `defer func() {}()`:**  This immediately screams "panic and recover."  `defer` executes functions after the surrounding function returns (or panics). `recover()` is used to catch panics.
* **Multiple `panic()` calls:**  The code intentionally triggers panics with different values.
* **A `for { break }` loop:** This loop executes only once due to the `break`.
* **The main function has two immediately invoked anonymous functions:** This is a way to create separate scopes and control the flow of deferred functions.

**2. Deconstructing the Nested `defer` Blocks:**

This is the core of understanding the code. I'll mentally (or physically, if it's complex) trace the execution order of the `defer` statements in the first anonymous function.

* **Innermost `defer func() { expect(3, recover()) }()`:**  This will run last within its nesting level. It expects to recover the value `3`.
* **`defer panic(3)`:** This will panic *before* the immediately preceding `defer` block runs. So, this panic will be recovered by the innermost `defer`.
* **`panic(2)`:** This happens *before* the `defer panic(3)`. This panic will be caught by the next outer `recover`.
* **`defer func() { expect(1, recover()) }()`:** This runs after the `panic(2)` is potentially recovered. It expects to recover the value `1`.
* **`panic(1)`:** This panic will be recovered by the `expect(1, recover())` block.

**3. Analyzing the Second Anonymous Function:**

* **`for { defer func() { defer panic(5) }() break }`:** The loop runs once. The outer `defer` will execute when the anonymous function finishes. Inside that `defer`, *another* panic with the value `5` is deferred.
* **`panic(4)`:** This panic happens *before* the deferred functions are executed in this anonymous function.

**4. Top-Level `defer`:**

* **`defer func() { expect(5, recover()) }()`:** This is the outermost `defer` in `main`. It will execute last. It expects to recover the value `5`.

**5. Putting it all together -  Tracing the Panic and Recover Flow:**

Now, I can start connecting the panics and recovers in the correct order:

1. **First anonymous function:**
   - `panic(1)` is called.
   - The `defer func() { expect(1, recover()) }()` recovers `1`.
   - Execution continues.
   - `panic(2)` is called.
   - The `defer func() { ... expect(3, recover()) ... }()` gets executed. Inside, `defer panic(3)` panics with `3`, which is recovered by `expect(3, recover())`. The original panic `2` is *not* recovered within this inner block.
2. **Second anonymous function:**
   - `panic(4)` is called.
   - The deferred function is executed: `defer panic(5)`.
   - This deferred function panics with `5`.
3. **Top-level `defer` in `main`:**
   - The panic with value `5` from the second anonymous function's deferred call is now the active panic.
   - The top-level `defer func() { expect(5, recover()) }()` recovers the value `5`.

**6. Identifying the Go Feature:**

The code demonstrably tests the interaction and order of execution of `panic` and `recover` within nested `defer` statements. Specifically, it highlights how `recover()` only catches the immediately preceding panic within the same goroutine and how multiple `defer` statements are executed in LIFO (Last-In, First-Out) order.

**7. Crafting the Go Code Example:**

The example needs to clearly illustrate the key behavior. A simple function with nested `defer` and `panic` calls, along with assertions using `recover()`, would be sufficient.

**8. Explaining the Logic with Input/Output:**

Since there are no direct inputs to `main` other than program execution, the "input" is essentially the program's structure. The "output" is the successful execution without the `log.Fatalf` calls. I'll focus on explaining the step-by-step panic and recovery.

**9. Command-Line Arguments:**

The provided code doesn't use any command-line arguments. So, this section can be skipped.

**10. Common Mistakes:**

Thinking about how someone might misunderstand `panic` and `recover`:

* **Expecting `recover()` to catch multiple panics:**  It only catches the most recent one in the current goroutine.
* **Incorrectly assuming the order of `defer` execution:** It's LIFO.
* **Not understanding the scope of `recover()`:**  It only works within a deferred function.

By following these steps, I could systematically analyze the code, understand its functionality, and generate a comprehensive explanation with a relevant Go example. The key is breaking down the nested `defer` blocks and tracing the flow of panics and recoveries.
这段 Go 代码片段的核心功能是**测试 Go 语言中 `panic` 和 `recover` 的行为，特别是当它们嵌套在多个 `defer` 语句中时，以及在循环结构中使用 `defer` 和 `panic` 的情况。**

更具体地说，它旨在验证在复杂的 `defer` 调用栈中，`recover()` 如何捕获最近发生的 `panic`，以及 `defer` 语句的执行顺序（后进先出，LIFO）。

**它所实现的是 Go 语言中 `panic` 和 `recover` 的行为测试。**

**Go 代码举例说明：**

```go
package main

import "fmt"

func main() {
	fmt.Println("程序开始")

	defer func() {
		if r := recover(); r != nil {
			fmt.Println("捕获到 panic:", r)
		}
	}()

	defer func() {
		panic("这是内部的 panic")
	}()

	panic("这是外部的 panic")

	fmt.Println("程序结束") // 这行代码不会被执行
}
```

**代码逻辑介绍（带假设的输入与输出）：**

**假设输入：** 运行上述 `issue43942.go` 代码。

**代码逻辑分析：**

1. **最外层的 `defer`：**  `defer func() { expect(5, recover()) }()` 被注册，它会在 `main` 函数结束（无论正常返回还是发生 panic）时执行。它期望捕获到的 `panic` 的值为 `5`。

2. **第一个匿名函数：**
   - `expect(nil, recover())`:  立即调用 `recover()`，此时没有发生 `panic`，因此 `recover()` 返回 `nil`，`expect` 函数会断言 `nil == nil`，通过。
   - 嵌套的 `defer` 链开始注册，按照后进先出的顺序：
     - `defer func() { ... panic(1) }()`
     - `defer func() { expect(1, recover()) }()`
     - `defer func() { ... defer panic(3); panic(2) }()`
     - `defer func() { expect(3, recover()) }()`
   - 执行到 `panic(1)`，触发 panic。
   - 倒数第二个注册的 `defer func() { expect(1, recover()) }()` 被执行，`recover()` 捕获到 `1`，`expect(1, 1)` 通过。
   - panic 恢复，继续执行。
   - 执行到 `panic(2)`，再次触发 panic。
   - 倒数第一个注册的 `defer func() { ... defer panic(3); panic(2) }()` 被执行。
     - 内部的 `defer panic(3)` 被注册。
     - `panic(2)` 再次触发 panic（虽然已经被外部的 `defer` 处理了，但是 `defer` 内部的代码仍然会执行）。
     - 内部的 `defer panic(3)` 执行，触发 panic，值为 `3`。
     - 最内层的 `defer func() { expect(3, recover()) }()` 执行，`recover()` 捕获到 `3`，`expect(3, 3)` 通过。

3. **第二个匿名函数：**
   - 进入一个无限循环 `for {}`，但是立即执行了 `break`，所以循环体只执行一次。
   - `defer func() { defer panic(5) }()` 被注册。
   - `panic(4)` 触发 panic。
   - 之前注册的 `defer func() { defer panic(5) }()` 被执行。
     - 内部的 `defer panic(5)` 被注册。
     - 由于外层的 `panic(4)` 尚未被捕获，内部的 `defer panic(5)` 会再次触发 panic，值为 `5`。

4. **最外层的 `defer` 执行：** `defer func() { expect(5, recover()) }()` 被执行，`recover()` 捕获到最后发生的 panic 的值 `5`，`expect(5, 5)` 通过。

**假设的输出：**  程序正常结束，没有任何错误日志输出，因为所有的 `panic` 都被 `recover` 并且 `expect` 函数的断言都成功了。

**命令行参数的具体处理：**

这段代码没有涉及任何命令行参数的处理。它是一个独立的 Go 程序，主要通过内部的函数调用和 `defer` 机制来测试 `panic` 和 `recover` 的行为。

**使用者易犯错的点：**

1. **误解 `recover()` 的作用范围：**  `recover()` 只能捕获**直接调用它的 `defer` 函数执行时**发生的 `panic`。如果 `panic` 发生在更深层的嵌套 `defer` 中，外部的 `recover()` 是无法直接捕获的，除非那个嵌套的 `defer` 重新 `panic` 了。

   **错误示例：**

   ```go
   package main

   import "fmt"

   func main() {
       defer func() {
           if r := recover(); r != nil {
               fmt.Println("捕获到 panic:", r) // 预期捕获 "inner panic"，但实际上不会
           }
       }()

       func() {
           defer func() {
               panic("inner panic")
           }()
       }()
   }
   ```
   在这个错误的例子中，外部的 `recover()` 无法捕获内部匿名函数中 `defer` 触发的 `panic`。

2. **不理解 `defer` 的执行顺序：**  `defer` 语句是后进先出的。容易错误地认为先写的 `defer` 会先执行。

   **错误示例：**

   ```go
   package main

   import "fmt"

   func main() {
       defer fmt.Println("first defer")
       defer fmt.Println("second defer")
   }
   // 输出：
   // second defer
   // first defer
   ```

3. **在 `recover()` 之后假设程序会像没有 `panic` 一样继续执行：**  `recover()` 只能阻止 `panic` 导致的程序崩溃。在调用 `recover()` 的 `defer` 函数执行完毕后，包含该 `defer` 的函数会像正常返回一样继续执行（如果 `recover()` 返回了非 `nil` 值），但 `panic` 发生点之后的代码是不会被执行的。

这段测试代码通过精心设计的嵌套 `defer` 和 `panic` 调用，细致地验证了 Go 语言中异常处理机制的各种场景和边界情况，确保 `panic` 和 `recover` 的行为符合预期。

Prompt: 
```
这是路径为go/test/fixedbugs/issue43942.go的go语言实现的一部分， 请归纳一下它的功能, 　
如果你能推理出它是什么go语言功能的实现，请用go代码举例说明, 
如果介绍代码逻辑，则建议带上假设的输入与输出，
如果涉及命令行参数的具体处理，请详细介绍一下，
如果有哪些使用者易犯错的点，请举例说明，没有则不必说明，

"""
// run

// Copyright 2022 The Go Authors. All rights reserved.
// Use of this source code is governed by a BSD-style
// license that can be found in the LICENSE file.

package main

import "log"

func main() {
	defer func() {
		expect(5, recover())
	}()
	func() {
		expect(nil, recover())
		defer func() {
			defer func() {
				defer func() {
					defer func() {
						expect(3, recover())
					}()
					defer panic(3)
					panic(2)
				}()
				defer func() {
					expect(1, recover())
				}()
				panic(1)
			}()
		}()
	}()
	func() {
		for {
			defer func() {
				defer panic(5)
			}()
			break
		}
		panic(4)
	}()
}

func expect(want, have interface{}) {
	if want != have {
		log.Fatalf("want %v, have %v", want, have)
	}
}

"""



```