Response: Let's break down the thought process for analyzing this Go code snippet and generating the comprehensive response.

**1. Initial Code Reading and Structure Identification:**

* **`package main` and `func main()`:**  Immediately recognize this as an executable Go program's entry point.
* **`defer func() { ... }()`:**  Spot the pervasive use of `defer`. This signals a focus on how deferred functions execute, especially in relation to `panic` and `recover`.
* **Nested anonymous functions:** Notice the heavy use of `func() { ... }()` constructs, creating various scopes. This likely plays a role in controlling the behavior of `panic` and `recover`.
* **`panic()` calls:** Multiple `panic(int)` calls are prominent. This strongly suggests the code is designed to test the behavior of panics and recoveries.
* **`recover()` calls:**  These appear in several `defer`red functions. The core purpose seems to be intercepting and handling panics.
* **Variable declaration (`var x = 123`):**  A simple variable declaration. Its placement and the `defer print(x)` suggest an investigation into variable scope and deferred function execution order.

**2. Step-by-Step Execution Simulation (Mental or with a Debugger):**

* **Outer `defer recover().(int)`:**  The outermost `defer` will execute after `main` finishes (or panics unhandled). It expects the recovered value to be an `int`.
* **First inner anonymous function:**
    * The type declaration `type _ int` and immediate return of an anonymous function are a bit of a distraction but don't directly impact the panic/recover flow. Recognize it's likely a test case detail.
    * The nested anonymous function with multiple `defer`s and `panic`s is the key. Trace the execution order:
        * `panic(1)` occurs.
        * The immediately preceding `defer func() { recover() }()` executes, catching the `panic(1)`. The recover returns `nil`.
        * The next `defer` chain involving `panic(2)` and `panic(3)`:
            * `panic(2)` occurs.
            * The inner `defer recover()` executes, catching `panic(2)`.
            * The outer `defer panic(3)` executes, initiating a new panic with value `3`.
        * The `defer func() {}()` executes (does nothing).
* **Second inner anonymous function:**
    * `defer print(x)` is scheduled.
    * The deeply nested anonymous function panics with `panic(4)`.
    * The inner `defer func() {}()` executes (does nothing).
* **The unhandled panic:** The `panic(4)` is not caught within its immediate scope. This panic propagates up.

**3. Connecting Panics and Recoveries:**

*  Realize that `recover()` only catches the *immediately preceding* panic in the same goroutine's call stack.
*  Understand the LIFO (Last-In, First-Out) nature of `defer` execution.

**4. Identifying the "Bug" and Its Fix:**

* The comment "// in the original issue, this defer was not executed (which is incorrect)" is a crucial clue. It points to a past bug related to deferred function execution.
*  The structure suggests the bug likely involved scenarios where a panic happened within a nested function, and a `defer` in an outer function wasn't correctly executed.
* In this specific example, the `panic(4)` should allow the `defer print(x)` to execute *before* the outermost `recover()` catches a value.

**5. Determining the Expected Output:**

* The `panic(4)` will propagate to the outermost `defer recover().(int)`. The `recover()` will return the value `4`.
* The `println` in the outer `defer` will print this recovered value.
*  Crucially, the `defer print(x)` (where `x` is 123) *should* have executed *before* the final recover.

**6. Formulating the Explanation:**

* **Functionality:** Explain the code's purpose as testing the interaction of `panic`, `recover`, and `defer`, specifically focusing on nested scenarios.
* **Go Feature:** Identify the feature as `panic` and `recover`, highlighting their role in error handling.
* **Code Example:** Create a simplified example to demonstrate the basic usage of `panic` and `recover`.
* **Code Logic (with Input/Output):**  Provide a detailed walkthrough of the code's execution flow, explicitly stating the panic values and where they are recovered (or not). Use the assumed input (no command-line arguments) and predict the output based on the execution analysis.
* **No Command-Line Arguments:**  Acknowledge the absence of command-line argument handling.
* **Common Mistakes:** Focus on the crucial misunderstanding of `recover()`'s scope and the LIFO nature of `defer`. Provide an illustrative incorrect usage example.

**7. Refining and Structuring the Response:**

* Organize the explanation into logical sections (Functionality, Go Feature, Code Example, etc.).
* Use clear and concise language.
* Highlight key terms like `panic`, `recover`, and `defer`.
* Ensure the code example is simple and easy to understand.
* Double-check the execution analysis for accuracy.

This structured approach, combining code reading, execution simulation, and understanding the underlying Go concepts, enables a thorough and accurate analysis of the provided code snippet. The key is to focus on the interaction of `defer`, `panic`, and `recover` within the nested function calls.
这段 Go 代码片段的主要功能是**测试 `panic` 和 `recover` 在嵌套 `defer` 调用中的执行顺序和作用域，特别是当涉及到匿名函数和类型别名时**。它旨在验证 Go 语言在特定复杂场景下 `defer` 语句的行为是否符合预期。

更具体地说，这段代码旨在复现并验证修复了一个与 `defer` 语句执行顺序相关的 bug（issue 48898）。在之前的 Go 版本中，某些嵌套 `defer` 语句可能不会被执行，而这个代码就是用来确保这些 `defer` 语句现在能够正确执行。

**它可以推理出这是对 Go 语言的 `panic` 和 `recover` 机制以及 `defer` 语句的执行顺序的测试。**

**Go 代码举例说明 `panic` 和 `recover`：**

```go
package main

import "fmt"

func mightPanic() {
	panic("something went wrong")
}

func main() {
	fmt.Println("Start")
	defer func() {
		if r := recover(); r != nil {
			fmt.Println("Recovered from:", r)
		}
	}()
	mightPanic()
	fmt.Println("End") // 这行代码不会被执行，因为 mightPanic 中发生了 panic
}
```

**代码逻辑介绍（带假设的输入与输出）：**

这段代码没有命令行参数输入。它的行为完全由其内部逻辑驱动。

**执行流程分析：**

1. **最外层的 `defer`：**  `defer func() { println(recover().(int)) }()`  这个 `defer` 语句会在 `main` 函数执行完毕（或发生未捕获的 `panic`）时执行。它尝试 `recover()`，并将恢复的值断言为 `int` 并打印出来。

2. **第一个匿名函数：**
   - `func() (_ [2]int) { type _ int; return }()`：这个匿名函数创建了一个名为 `_` 的类型别名，其底层类型是 `int`。它返回一个类型为 `[2]int` 的值，但由于没有实际赋值，返回的是零值。这个函数本身对 `panic` 和 `recover` 的流程没有直接影响，可能只是为了增加代码的复杂性。
   - **第二个嵌套匿名函数（关键部分）：**
     - **内部 `defer` 链：**
       - `defer func() { defer func() { recover() }() ; defer panic(3); panic(2) }()`：
         - 首先 `panic(2)` 被调用。
         - 然后，外层的 `defer` 执行。在这个 `defer` 中：
           - `panic(3)` 被 `defer`，这意味着它会在内部的 `recover()` 执行 *之后* 执行。
           - 内部的 `defer func() { recover() }()` 执行，它会捕获到 `panic(2)`，`recover()` 返回非 `nil` 值（即 `2`）。
         - 因此，这个 `defer` 块执行完毕后，会触发一个新的 `panic(3)`。
       - `defer func() { recover() }()`：这个 `defer` 语句会捕获到前面触发的 `panic(3)`，`recover()` 返回非 `nil` 值（即 `3`）。
       - `panic(1)`：最初的 `panic(1)` 被调用。
     - **第三个 `defer`：** `defer func() {}()`：这个 `defer` 语句什么也不做，它的存在可能是为了测试 `defer` 的执行顺序。

3. **变量声明和第二个主要匿名函数：**
   - `var x = 123`：声明并初始化一个整型变量 `x`。
   - `func() { defer print(x); func() { defer func() {}(); panic(4) }() }()`：
     - **内部匿名函数：**
       - `defer func() {}()`：一个空的 `defer` 语句。
       - `panic(4)`：触发一个 `panic`，值为 `4`。
     - **外部 `defer`：** `defer print(x)`：这个 `defer` 语句会在包含它的匿名函数执行完毕后执行，打印变量 `x` 的值（`123`）。**关键点在于，在 issue 48898 修复之前，这个 `defer` 语句可能不会被执行。**

**假设的输出：**

根据代码的逻辑和 `panic`/`recover` 的行为，以及 issue 48898 已修复的假设，输出应该是：

```
123
4
```

**输出解释：**

1. **`123`：**  当内部的 `panic(4)` 发生时，控制权会向上冒泡。在包含 `panic(4)` 的匿名函数退出前，其 `defer print(x)` 会被执行，打印出 `x` 的值 `123`。
2. **`4`：** 最外层的 `defer func() { println(recover().(int)) }()` 会在 `main` 函数即将退出时执行。此时，由于内部的 `panic(4)` 没有被中间的 `recover` 完全处理，它会一直冒泡到 `main` 函数。最外层的 `recover()` 会捕获到这个 `panic`，并返回其值 `4`，然后被 `println` 打印出来。

**使用者易犯错的点：**

1. **误解 `recover()` 的作用域：**  `recover()` 只能捕获直接调用它的 `defer` 函数所在 Goroutine 中发生的 `panic`。如果 `panic` 发生在更深的嵌套函数中，并且没有被中间的 `recover` 捕获，那么它会继续向上冒泡。

   **错误示例：**

   ```go
   package main

   import "fmt"

   func inner() {
       panic("oops")
   }

   func outer() {
       defer func() {
           if r := recover(); r != nil {
               fmt.Println("Recovered in outer:", r)
           }
       }()
       inner()
   }

   func main() {
       outer()
       fmt.Println("程序继续执行") // 这行不会执行
   }
   ```
   在这个例子中，`recover()` 在 `outer` 函数中，它可以捕获 `inner` 函数中发生的 `panic`。但是，如果 `recover()` 不存在，`panic` 会导致程序终止。

2. **混淆 `defer` 的执行顺序：** `defer` 语句是后进先出 (LIFO) 的。这意味着最后 `defer` 的语句最先执行。在复杂的嵌套 `defer` 场景中，很容易弄混执行顺序。

   **错误示例：**

   ```go
   package main

   import "fmt"

   func main() {
       defer fmt.Println("first defer")
       defer fmt.Println("second defer")
   }
   ```
   输出将是：
   ```
   second defer
   first defer
   ```

这段 `issue48898.go` 的代码就是一个精心设计的测试用例，旨在覆盖 `panic`、`recover` 和 `defer` 相互作用的复杂场景，确保 Go 语言的运行时行为符合预期。 理解这段代码需要对 Go 语言的错误处理机制和 `defer` 语句有深入的理解。

### 提示词
```
这是路径为go/test/fixedbugs/issue48898.go的go语言实现的一部分， 请归纳一下它的功能, 　
如果你能推理出它是什么go语言功能的实现，请用go代码举例说明, 
如果介绍代码逻辑，则建议带上假设的输入与输出，
如果涉及命令行参数的具体处理，请详细介绍一下，
如果有哪些使用者易犯错的点，请举例说明，没有则不必说明，
```

### 源代码
```
// run

// Copyright 2021 The Go Authors. All rights reserved.
// Use of this source code is governed by a BSD-style
// license that can be found in the LICENSE file.

package main

func main() {
	defer func() {
		println(recover().(int))
	}()
	func() {
		func() (_ [2]int) { type _ int; return }()
		func() {
			defer func() {
				defer func() {
					recover()
				}()
				defer panic(3)
				panic(2)
			}()
			defer func() {
				recover()
			}()
			panic(1)
		}()
		defer func() {}()
	}()

	var x = 123
	func() {
		// in the original issue, this defer was not executed (which is incorrect)
		defer print(x)
		func() {
			defer func() {}()
			panic(4)
		}()
	}()
}
```