Response: Let's break down the thought process for analyzing this Go code snippet.

**1. Initial Scan and Overall Purpose:**

The first thing I do is a quick read-through to get a general sense of what's happening. I see `package main`, `import`, function definitions (`foo`, `test`, `bar`, `testVariadic`, `main`), `defer recover()`, and calls to `runtime.Callers` and `runtime.CallersFrames`. The presence of `defer recover()` and the stack trace analysis strongly suggests this code is about error handling and inspecting the call stack during a panic.

**2. Analyzing `test()` and `testVariadic()`:**

These functions look very similar. The core structure is:

* `defer recover()` block: This is the key to handling panics.
* `var v []int`: An empty integer slice is declared.
* Function call with `v[0]`:  This is the action that *will* cause a panic because accessing `v[0]` on an empty slice is an out-of-bounds error.
* Stack trace inspection inside `recover()`: This is where the core logic lies.

**3. Decoding the Stack Trace Inspection:**

The code within the `recover()` block is crucial:

* `runtime.Callers(0, pcs)`: This gets the program counters (memory addresses) of the functions in the current call stack. The `0` means "get all frames."
* `runtime.CallersFrames(pcs)`: This turns the program counters into more human-readable stack frame information (function name, file, line number, etc.).
* The `for` loop and `frames.Next()`: This iterates through the stack frames.
* `if f.Function == "main.foo"` (or `main.bar`): This is the core assertion. The code is checking if the *expected* function call that caused the panic is present in the stack trace.
* `println("did not expect to see call to foo in stack trace")` and `os.Exit(1)`: If the function call *is* found, the test fails.

**4. Forming the Hypothesis:**

Based on the above analysis, the core functionality seems to be: **verifying that function calls immediately preceding a panic caused by an out-of-bounds slice access are *not* visible in the recovered stack trace.**

This is a bit counter-intuitive. Normally, you'd expect the function causing the error to be on the stack. The code is explicitly asserting the *opposite*. This leads to the hypothesis that this code is demonstrating some kind of optimization or behavior within the Go runtime regarding panics in certain scenarios.

**5. Identifying the Go Feature:**

The key here is the out-of-bounds slice access within a function call. This leads to thinking about how Go handles such errors and how it constructs the stack trace during a panic. The fact that the immediate caller (`foo` or `bar`) isn't on the stack suggests that the runtime might be directly jumping to the `recover()` handler without fully unwinding the stack to the point of the function call. This is likely an optimization.

**6. Creating a Demonstrative Go Example:**

To illustrate this, I would create a simple Go program that mirrors the structure of the provided code, ensuring the same panic-causing scenario:

```go
package main

import "fmt"

func causePanic() {
	var s []int
	_ = s[0] // This will panic
}

func wrapper() {
	causePanic()
}

func main() {
	defer func() {
		if r := recover(); r != nil {
			// ... (inspect stack trace like in the original code) ...
			fmt.Println("Recovered from panic:", r)
		}
	}()
	wrapper()
}
```

Then, I would modify the stack trace inspection within the `recover()` block to confirm that `causePanic` *doesn't* appear in the trace.

**7. Explaining the Logic with Input/Output:**

To explain the logic clearly, I would consider the execution flow:

* **Input:**  No explicit input in this code, but conceptually, it's the execution of the `test` and `testVariadic` functions.
* **Process:**
    1. `test()` is called.
    2. `defer recover()` is set up.
    3. `foo(v[0])` is called. Accessing `v[0]` panics.
    4. The `recover()` function catches the panic.
    5. `runtime.Callers` and `runtime.CallersFrames` are used to get the stack trace.
    6. The code iterates through the frames, specifically checking for "main.foo".
    7. Since "main.foo" is *not* expected, the loop should complete without exiting.
    8. The same process happens for `testVariadic()` and `main.bar`.
* **Output:** If the assertion holds true (the functions aren't in the stack trace), the program will complete without printing the error message and exiting. If the assertion fails, it will print the error message and exit with code 1.

**8. Describing Command Line Arguments:**

In this specific example, there are no command-line arguments being processed. I would explicitly state this.

**9. Identifying Potential Pitfalls:**

The key pitfall here is misunderstanding how Go handles panics and stack traces in optimized scenarios. Developers might expect to see the immediate caller of a panicking function in the stack trace, but this example demonstrates that's not always the case. I would provide an example of this misunderstanding.

**Self-Correction/Refinement during the Process:**

* **Initial thought:** Maybe this is about filtering stack traces. *Correction:* The code isn't filtering; it's asserting the *absence* of specific functions.
* **Initial thought:** Perhaps this is related to inline functions. *Correction:* While inlining could potentially affect the stack, the core issue is the optimization related to immediate panics. The example uses simple, non-inlined functions for clarity.
* **Focus on the "why":** It's important not just to describe *what* the code does, but *why* it might be designed this way. The optimization angle is crucial.

By following these steps, I can systematically analyze the code, understand its purpose, hypothesize the underlying Go feature, create illustrative examples, and clearly explain the functionality and potential pitfalls.
这段Go语言代码片段主要用于测试在特定情况下，当发生 `panic` 时，Go 运行时捕获到的调用栈信息是否符合预期。更具体地说，它似乎在测试 **当由于切片越界访问（`panic: runtime error: index out of range`）而发生 panic 时，直接调用导致 panic 的函数是否会出现在 `recover` 捕获到的堆栈跟踪中**。

**功能归纳:**

这段代码的核心功能是验证 Go 语言在处理由切片越界访问导致的 `panic` 时，是否会省略直接导致 panic 的函数在 `recover` 中获取到的堆栈信息。如果直接导致 panic 的函数出现在堆栈中，测试将会失败。

**推断的 Go 语言功能实现:**

这部分代码很可能与 Go 运行时处理 `panic` 和生成堆栈跟踪的机制有关。它似乎在验证一种优化或者特定的行为，即在某些简单的、可以直接定位到 panic 原因的情况下，运行时可能会省略一些中间调用帧，以简化堆栈信息。

**Go 代码举例说明:**

```go
package main

import (
	"fmt"
	"runtime"
)

func causePanic() {
	var s []int
	_ = s[0] // 访问越界，会触发 panic
}

func wrapper() {
	causePanic()
}

func main() {
	defer func() {
		if r := recover(); r != nil {
			fmt.Println("Recovered from panic:", r)
			pcs := make([]uintptr, 10)
			n := runtime.Callers(0, pcs)
			pcs = pcs[:n]
			frames := runtime.CallersFrames(pcs)
			found := false
			for {
				f, more := frames.Next()
				if f.Function == "main.causePanic" {
					fmt.Println("Error: Expected main.causePanic NOT to be in stack trace")
					found = true
				}
				if !more {
					break
				}
			}
			if !found {
				fmt.Println("Success: main.causePanic not found in stack trace")
			}
		}
	}()
	wrapper()
}
```

在这个例子中，`causePanic` 函数直接导致了 panic。根据 `issue19799.go` 的逻辑，我们期望在 `recover` 中获取到的堆栈信息中看不到 `main.causePanic`。

**代码逻辑介绍 (带假设的输入与输出):**

**`test()` 函数:**

1. **假设输入:** 无特定输入。
2. **`defer func() { ... }()`:** 这是一个延迟执行的匿名函数，用于捕获可能发生的 `panic`。
3. **`recover()`:** 如果发生 `panic`，`recover()` 会捕获该 `panic` 并返回其传递的值（如果有）。如果没有 `panic`，则返回 `nil`。
4. **`runtime.Callers(0, pcs)`:** 获取当前 goroutine 的调用栈信息。`0` 表示跳过 0 层调用栈（即从当前函数开始），`pcs` 是一个 `uintptr` 类型的切片，用于存储程序计数器 (Program Counter)。
   * **假设 `pcs` 容量为 10，实际调用栈深度小于 10。**
5. **`pcs = pcs[:n]`:**  截取 `pcs` 切片，使其长度与实际获取到的调用栈帧数一致。
6. **`runtime.CallersFrames(pcs)`:** 将程序计数器转换为可读的堆栈帧信息。
7. **`for { ... }`:** 遍历堆栈帧。
8. **`f, more := frames.Next()`:** 获取下一个堆栈帧。如果已到达堆栈底部，`more` 为 `false`。
9. **`if f.Function == "main.foo"`:** 检查当前堆栈帧对应的函数名是否为 `"main.foo"`。
   * **假设在由于 `foo(v[0])` 导致的 `panic` 中，运行时优化了堆栈信息，没有包含 `main.foo`。**
10. **`println("did not expect to see call to foo in stack trace")` 和 `os.Exit(1)`:** 如果在堆栈中找到了 `"main.foo"`，则表示测试失败，程序退出。
11. **`var v []int` 和 `foo(v[0])`:**  定义一个空的整数切片 `v`，并尝试访问其第一个元素 `v[0]`。由于切片为空，这将导致 `panic: runtime error: index out of range`。

**`testVariadic()` 函数:**

逻辑与 `test()` 函数基本相同，只是调用的函数是可变参数函数 `bar`。目的是测试可变参数函数在这种 panic 场景下的堆栈信息。

**`main()` 函数:**

依次调用 `test()` 和 `testVariadic()` 函数来执行测试。

**假设的输入与输出:**

当运行此程序时，由于 `v[0]` 访问越界，`test()` 和 `testVariadic()` 函数都会发生 `panic`。`recover()` 会捕获这些 `panic`。

* **`test()` 函数的输出 (假设 `main.foo` 不在堆栈中):** 程序不会打印 "did not expect to see call to foo in stack trace" 并退出。
* **`testVariadic()` 函数的输出 (假设 `main.bar` 不在堆栈中):** 程序不会打印 "did not expect to see call to bar in stack trace" 并退出。

如果所有的断言都成立（即 `main.foo` 和 `main.bar` 不在堆栈中），程序将正常结束。否则，程序会因为 `os.Exit(1)` 而退出，表示测试失败。

**命令行参数的具体处理:**

这段代码没有涉及任何命令行参数的处理。

**使用者易犯错的点:**

这段代码主要是为了测试 Go 运行时的行为，而不是供普通使用者直接使用的代码。但是，可以从中了解到一些关于 `panic` 和 `recover` 的注意事项：

* **错误地认为 `recover` 会捕获所有级别的调用栈信息:** 开发者可能会期望在 `recover` 中能看到导致 `panic` 的完整调用链。然而，如这段代码所示，Go 运行时在某些情况下可能会省略一些调用帧。这通常发生在可以直接确定 `panic` 原因的简单场景中，例如直接访问越界的切片。
* **过度依赖 `recover` 来处理所有错误:** 虽然 `recover` 可以捕获 `panic`，但它主要用于处理无法预见的、程序级的错误。对于可预见的错误，应该使用更明确的错误处理机制（例如，返回 `error` 类型）。
* **在不理解其行为的情况下检查堆栈信息:** 直接解析和依赖堆栈信息的格式和内容是脆弱的，因为 Go 运行时的堆栈信息格式可能会在不同版本之间发生变化。

**示例说明易犯错的点:**

假设一个开发者有以下代码：

```go
package main

import (
	"fmt"
	"runtime"
)

func inner() {
	var s []int
	_ = s[0] // 故意触发 panic
}

func outer() {
	inner()
}

func main() {
	defer func() {
		if r := recover(); r != nil {
			fmt.Println("Recovered:", r)
			pcs := make([]uintptr, 32)
			n := runtime.Callers(0, pcs)
			pcs = pcs[:n]
			frames := runtime.CallersFrames(pcs)
			for {
				frame, more := frames.Next()
				fmt.Printf("- %s\n", frame.Function)
				if !more {
					break
				}
			}
		}
	}()
	outer()
}
```

这个开发者可能期望在 `recover` 的堆栈信息中看到 `main.inner` 和 `main.outer`。但是，根据 `issue19799.go` 的测试，如果运行时进行了优化，可能只会看到 `main.main`（以及 `runtime` 的相关函数）。如果开发者依赖于看到 `main.inner` 或 `main.outer` 来进行某些处理，就会出错。

总而言之，`issue19799.go` 这段代码是 Go 语言自身测试套件的一部分，用于验证运行时在处理特定类型的 `panic` 时，堆栈信息的生成是否符合预期。它揭示了 Go 运行时可能对堆栈信息进行优化的行为。

### 提示词
```
这是路径为go/test/fixedbugs/issue19799.go的go语言实现的一部分， 请归纳一下它的功能, 　
如果你能推理出它是什么go语言功能的实现，请用go代码举例说明, 
如果介绍代码逻辑，则建议带上假设的输入与输出，
如果涉及命令行参数的具体处理，请详细介绍一下，
如果有哪些使用者易犯错的点，请举例说明，没有则不必说明，
```

### 源代码
```
// run

// Copyright 2017 The Go Authors. All rights reserved.
// Use of this source code is governed by a BSD-style
// license that can be found in the LICENSE file.

package main

import (
	"os"
	"runtime"
)

func foo(x int) int {
	return x + 1
}

func test() {
	defer func() {
		if r := recover(); r != nil {
			pcs := make([]uintptr, 10)
			n := runtime.Callers(0, pcs)
			pcs = pcs[:n]
			frames := runtime.CallersFrames(pcs)
			for {
				f, more := frames.Next()
				if f.Function == "main.foo" {
					println("did not expect to see call to foo in stack trace")
					os.Exit(1)
				}
				if !more {
					break
				}
			}
		}
	}()
	var v []int
	foo(v[0])
}

func bar(x ...int) int {
	return x[0] + 1
}

func testVariadic() {
	defer func() {
		if r := recover(); r != nil {
			pcs := make([]uintptr, 10)
			n := runtime.Callers(0, pcs)
			pcs = pcs[:n]
			frames := runtime.CallersFrames(pcs)
			for {
				f, more := frames.Next()
				if f.Function == "main.bar" {
					println("did not expect to see call to bar in stack trace")
					os.Exit(1)
				}
				if !more {
					break
				}
			}
		}
	}()
	var v []int
	bar(v[0])
}

func main() {
	test()
	testVariadic()
}
```